<mujoco>
    <option gravity = "0 0 10" integrator = "RK4"/>

    <asset>
        <texture name = "grid" type = "2d" builtin="checker" rgb1 = "0.1 0.2 0.3" 
        rgb2 = "0.2 0.3 0.4" width = "300" height = "300"/>
        <material name = "grid" texture = "grid" texrepeat = "8 8" reflectance = "0.2"/>
    </asset>

    <worldbody>

        <camera name="camera1" xyaxes = "0 -1 0 0 0 1" pos = "0 1 0"/>
        <geom name = "floor" type = "plane" pos = "0 0 0" size = "10 10 0.1" material = "grid"/>

        <body name = "ball" euler = "0 0 0">

            <joint name="swingy" type= "hinge" axis="0 0 1" pos="0 0 0"/>
            <geom name="ball" type="sphere" size="0.5" rgba = "1 1 1 1" pos = "1 1 1" />

        </body>


    </worldbody>
</mujoco>